<?xml version='1.0'?>
<sdf version='1.4'>
	<model name='ball_drone'>
		<link name='frame'>
			<inertial>
				<pose>0 0 0.07 0 0 0</pose>
				<inertia>
					<ixx>0.013</ixx>
					<ixy>-0.0049</ixy>
					<ixz>-0.0063</ixz>
					<iyy>0.013</iyy>
					<iyz>-0.0063</iyz>
					<izz>0.0098</izz>
				</inertia>
				<mass>1.0</mass>
        	</inertial>
			<visual name='visual'>
				<pose>-0.0725 0.105 0 1.570796 0 0</pose>
				<geometry>
					<mesh>
						<uri>model://ball_drone/meshes/ball_drone.stl</uri>
						<scale>0.001 0.001 0.001</scale>
					</mesh>
				</geometry>
			</visual>
			<collision name='collision'>
				<pose>0 0 0.12 0 0 0</pose>
				<geometry>
					<sphere>
						<radius>0.12</radius>
					</sphere>
				</geometry>
			</collision>
		</link>

		<link name='stand'>
			<inertial>
				<inertia>
					<ixx>0</ixx>
					<ixy>0</ixy>
					<ixz>0</ixz>
					<iyy>0</iyy>
					<iyz>0</iyz>
					<izz>0</izz>
				</inertia>
				<mass>0.00001</mass>
        	</inertial>
			<visual name='visual'>
				<geometry>
					<empty></empty>
				</geometry>
			</visual>
			<collision name='collision'>
				<pose>0 0 0.01 0 0 0</pose>
				<geometry>
					<cylinder>
						<radius>0.1</radius>
						<length>0.02</length>
					</cylinder>
				</geometry>
			</collision>
		</link>
		<joint name='stand_joint' type='fixed'>
			<parent>frame</parent>
			<child>stand</child>
		</joint>


		<!-- Sensors -->
		<include>
			<uri>model://imu</uri>
			<pose>0 0 0.07 0 0 0</pose>
			<name>imu</name>
		</include>
		<joint name='imu_joint' type='fixed'>
			<child>imu::link</child>
			<parent>frame</parent>
			<!-- <axis>
				<xyz>1 0 0</xyz>
				<limit>
				<lower>0</lower>
				<upper>0</upper>
				<effort>0</effort>
				<velocity>0</velocity>
				</limit>
				<dynamics>
				<spring_reference>0</spring_reference>
				<spring_stiffness>0</spring_stiffness>
				</dynamics>
				<use_parent_model_frame>1</use_parent_model_frame>
			</axis> -->
		</joint>
		<include>
			<uri>model://gps</uri>
			<pose>0 0 0.07 0 0 0</pose>
			<name>gps0</name>
		</include>
		<joint name='gps0_joint' type='fixed'>
			<child>gps0::link</child>
			<parent>frame</parent>
		</joint>
		<include>
			<uri>model://magnetometer</uri>
			<pose>0 0 0.07 0 0 0</pose>
			<name>mag</name>
		</include>
		<joint name='mag_joint' type='fixed'>
			<child>mag::link</child>
			<parent>frame</parent>
		</joint>
		<plugin name='groundtruth_plugin' filename='libgazebo_groundtruth_plugin.so'>
			<robotNamespace/>
		</plugin>
		<plugin name='barometer_plugin' filename='libgazebo_barometer_plugin.so'>
			<robotNamespace/>
			<pubRate>50</pubRate>
			<baroTopic>/baro</baroTopic>
			<baroDriftPaPerSec>0</baroDriftPaPerSec>
		</plugin>

		<!-- rotor -->
		<link name='rotor_0'>
			<pose frame=''>0.07 0.07 0.18 -0.6154797 0.5235988 -0.1699185</pose>
			<inertial>
				<pose frame=''>0 0 0 0 -0 0</pose>
				<mass>0.005</mass>
				<inertia>
				<ixx>9.75e-07</ixx>
				<ixy>0</ixy>
				<ixz>0</ixz>
				<iyy>0.000273104</iyy>
				<iyz>0</iyz>
				<izz>0.000274004</izz>
				</inertia>
			</inertial>
			<collision name='rotor_0_collision'>
				<pose frame=''>0 0 0 0 -0 0</pose>
				<geometry>
				<cylinder>
					<length>0.003</length>
					<radius>0.032</radius>
				</cylinder>
				</geometry>
				<surface>
				<contact>
					<ode/>
				</contact>
				<friction>
					<ode/>
				</friction>
				</surface>
			</collision>
			<visual name='rotor_0_visual'>
				<pose frame=''>0 0 0 0 -0 0</pose>
				<geometry>
				<mesh>
					<scale>0.25 0.25 0.25</scale>
					<uri>model://iris/meshes/iris_prop_ccw.dae</uri>
				</mesh>
				</geometry>
				<material>
				<script>
					<name>Gazebo/Blue</name>
					<uri>file://media/materials/scripts/gazebo.material</uri>
				</script>
				</material>
			</visual>
			<gravity>1</gravity>
			<velocity_decay/>
		</link>
		<joint name='rotor_0_joint' type='revolute'>
			<child>rotor_0</child>
			<parent>frame</parent>
			<axis>
				<xyz>0.5 0.5 0.71071068</xyz>
				<limit>
				<lower>-1e+16</lower>
				<upper>1e+16</upper>
				</limit>
				<dynamics>
					<spring_reference>0</spring_reference>
					<spring_stiffness>0</spring_stiffness>
				</dynamics>
				<use_parent_model_frame>1</use_parent_model_frame>
			</axis>
		</joint>
		<link name='rotor_1'>
		<pose frame=''>-0.07 0.07 0.18 -0.6154797 -0.5235988 0.1699185</pose>
		<inertial>
			<pose frame=''>0 0 0 0 -0 0</pose>
			<mass>0.005</mass>
			<inertia>
			<ixx>9.75e-07</ixx>
			<ixy>0</ixy>
			<ixz>0</ixz>
			<iyy>0.000273104</iyy>
			<iyz>0</iyz>
			<izz>0.000274004</izz>
			</inertia>
		</inertial>
		<collision name='rotor_1_collision'>
			<pose frame=''>0 0 0 0 -0 0</pose>
			<geometry>
			<cylinder>
				<length>0.003</length>
				<radius>0.032</radius>
			</cylinder>
			</geometry>
			<surface>
			<contact>
				<ode/>
			</contact>
			<friction>
				<ode/>
			</friction>
			</surface>
		</collision>
		<visual name='rotor_1_visual'>
			<pose frame=''>0 0 0 0 -0 0</pose>
			<geometry>
			<mesh>
				<scale>0.25 0.25 0.25</scale>
				<uri>model://iris/meshes/iris_prop_ccw.dae</uri>
			</mesh>
			</geometry>
			<material>
			<script>
				<name>Gazebo/DarkGrey</name>
				<uri>file://media/materials/scripts/gazebo.material</uri>
			</script>
			</material>
		</visual>
		<gravity>1</gravity>
		<velocity_decay/>
		</link>
		<joint name='rotor_1_joint' type='revolute'>
			<child>rotor_1</child>
			<parent>frame</parent>
			<axis>
				<xyz>-0.5 0.5 0.71071068</xyz>
				<limit>
				<lower>-1e+16</lower>
				<upper>1e+16</upper>
				</limit>
				<dynamics>
				<spring_reference>0</spring_reference>
				<spring_stiffness>0</spring_stiffness>
				</dynamics>
				<use_parent_model_frame>1</use_parent_model_frame>
			</axis>
		</joint>
		<link name='rotor_2'>
		<pose frame=''>0.07 -0.07 0.18 0.6154797 0.5235988 0.1699185</pose>
		<inertial>
			<pose frame=''>0 0 0 0 -0 0</pose>
			<mass>0.005</mass>
			<inertia>
			<ixx>9.75e-07</ixx>
			<ixy>0</ixy>
			<ixz>0</ixz>
			<iyy>0.000273104</iyy>
			<iyz>0</iyz>
			<izz>0.000274004</izz>
			</inertia>
		</inertial>
		<collision name='rotor_2_collision'>
			<pose frame=''>0 0 0 0 -0 0</pose>
			<geometry>
			<cylinder>
				<length>0.003</length>
				<radius>0.032</radius>
			</cylinder>
			</geometry>
			<surface>
			<contact>
				<ode/>
			</contact>
			<friction>
				<ode/>
			</friction>
			</surface>
		</collision>
		<visual name='rotor_2_visual'>
			<pose frame=''>0 0 0 0 -0 0</pose>
			<geometry>
			<mesh>
				<scale>0.25 0.25 0.25</scale>
				<uri>model://iris/meshes/iris_prop_cw.dae</uri>
			</mesh>
			</geometry>
			<material>
			<script>
				<name>Gazebo/Blue</name>
				<uri>file://media/materials/scripts/gazebo.material</uri>
			</script>
			</material>
		</visual>
		<gravity>1</gravity>
		<velocity_decay/>
		</link>
		<joint name='rotor_2_joint' type='revolute'>
			<child>rotor_2</child>
			<parent>frame</parent>
			<axis>
				<xyz>0.5 -0.5 0.71071068</xyz>
				<limit>
				<lower>-1e+16</lower>
				<upper>1e+16</upper>
				</limit>
				<dynamics>
				<spring_reference>0</spring_reference>
				<spring_stiffness>0</spring_stiffness>
				</dynamics>
				<use_parent_model_frame>1</use_parent_model_frame>
			</axis>
		</joint>
		<link name='rotor_3'>
		<pose frame=''>-0.07 -0.07 0.18 0.6154797 -0.5235988 -0.1699185</pose>
		<inertial>
			<pose frame=''>0 0 0 0 -0 0</pose>
			<mass>0.005</mass>
			<inertia>
			<ixx>9.75e-07</ixx>
			<ixy>0</ixy>
			<ixz>0</ixz>
			<iyy>0.000273104</iyy>
			<iyz>0</iyz>
			<izz>0.000274004</izz>
			</inertia>
		</inertial>
		<collision name='rotor_3_collision'>
			<pose frame=''>0 0 0 0 -0 0</pose>
			<geometry>
			<cylinder>
				<length>0.003</length>
				<radius>0.032</radius>
			</cylinder>
			</geometry>
			<surface>
			<contact>
				<ode/>
			</contact>
			<friction>
				<ode/>
			</friction>
			</surface>
		</collision>
		<visual name='rotor_3_visual'>
			<pose frame=''>0 0 0 0 -0 0</pose>
			<geometry>
			<mesh>
				<scale>0.25 0.25 0.25</scale>
				<uri>model://iris/meshes/iris_prop_cw.dae</uri>
			</mesh>
			</geometry>
			<material>
			<script>
				<name>Gazebo/DarkGrey</name>
				<uri>file://media/materials/scripts/gazebo.material</uri>
			</script>
			</material>
		</visual>
		<gravity>1</gravity>
		<velocity_decay/>
		</link>
		<joint name='rotor_3_joint' type='revolute'>
			<child>rotor_3</child>
			<parent>frame</parent>
			<axis>
				<xyz>-0.5 -0.5 0.71071068</xyz>
				<limit>
				<lower>-1e+16</lower>
				<upper>1e+16</upper>
				</limit>
				<dynamics>
				<spring_reference>0</spring_reference>
				<spring_stiffness>0</spring_stiffness>
				</dynamics>
				<use_parent_model_frame>1</use_parent_model_frame>
			</axis>
		</joint>
		<link name='rotor_4'>
		<!-- <pose frame=''>0.07 0.07 0.03 -2.5261129 0.5235988 -1.4008779</pose> -->
		<pose frame=''>0.07 0.07 0.03 0.6154797 -0.5235988 -0.1699185</pose>
		<inertial>
			<pose frame=''>0 0 0 0 -0 0</pose>
			<mass>0.005</mass>
			<inertia>
			<ixx>9.75e-07</ixx>
			<ixy>0</ixy>
			<ixz>0</ixz>
			<iyy>0.000273104</iyy>
			<iyz>0</iyz>
			<izz>0.000274004</izz>
			</inertia>
		</inertial>
		<collision name='rotor_4_collision'>
			<pose frame=''>0 0 0 0 -0 0</pose>
			<geometry>
			<cylinder>
				<length>0.003</length>
				<radius>0.032</radius>
			</cylinder>
			</geometry>
			<surface>
			<contact>
				<ode/>
			</contact>
			<friction>
				<ode/>
			</friction>
			</surface>
		</collision>
		<visual name='rotor_4_visual'>
			<pose frame=''>0 0 0 0 -0 0</pose>
			<geometry>
			<mesh>
				<scale>0.25 0.25 0.25</scale>
				<uri>model://iris/meshes/iris_prop_cw.dae</uri>
			</mesh>
			</geometry>
			<material>
			<script>
				<name>Gazebo/DarkGrey</name>
				<uri>file://media/materials/scripts/gazebo.material</uri>
			</script>
			</material>
		</visual>
		<gravity>1</gravity>
		<velocity_decay/>
		</link>
		<joint name='rotor_4_joint' type='revolute'>
			<child>rotor_4</child>
			<parent>frame</parent>
			<axis>
				<xyz>-0.5 -0.5 0.71071068</xyz>
				<limit>
				<lower>-1e+16</lower>
				<upper>1e+16</upper>
				</limit>
				<dynamics>
				<spring_reference>0</spring_reference>
				<spring_stiffness>0</spring_stiffness>
				</dynamics>
				<use_parent_model_frame>1</use_parent_model_frame>
			</axis>
		</joint>
		<link name='rotor_5'>
		<!-- <pose frame=''>-0.07 0.07 0.03 -2.5261129 -0.5235988 1.4008779</pose> -->
		<pose frame=''>-0.07 0.07 0.03 0.6154797 0.5235988 0.1699185</pose>
		<inertial>
			<pose frame=''>0 0 0 0 -0 0</pose>
			<mass>0.005</mass>
			<inertia>
			<ixx>9.75e-07</ixx>
			<ixy>0</ixy>
			<ixz>0</ixz>
			<iyy>0.000273104</iyy>
			<iyz>0</iyz>
			<izz>0.000274004</izz>
			</inertia>
		</inertial>
		<collision name='rotor_5_collision'>
			<pose frame=''>0 0 0 0 -0 0</pose>
			<geometry>
			<cylinder>
				<length>0.003</length>
				<radius>0.032</radius>
			</cylinder>
			</geometry>
			<surface>
			<contact>
				<ode/>
			</contact>
			<friction>
				<ode/>
			</friction>
			</surface>
		</collision>
		<visual name='rotor_5_visual'>
			<pose frame=''>0 0 0 0 -0 0</pose>
			<geometry>
			<mesh>
				<scale>0.25 0.25 0.25</scale>
				<uri>model://iris/meshes/iris_prop_cw.dae</uri>
			</mesh>
			</geometry>
			<material>
			<script>
				<name>Gazebo/DarkGrey</name>
				<uri>file://media/materials/scripts/gazebo.material</uri>
			</script>
			</material>
		</visual>
		<gravity>1</gravity>
		<velocity_decay/>
		</link>
		<joint name='rotor_5_joint' type='revolute'>
			<child>rotor_5</child>
			<parent>frame</parent>
			<axis>
				<xyz>0.5 -0.5 0.71071068</xyz>
				<limit>
				<lower>-1e+16</lower>
				<upper>1e+16</upper>
				</limit>
				<dynamics>
				<spring_reference>0</spring_reference>
				<spring_stiffness>0</spring_stiffness>
				</dynamics>
				<use_parent_model_frame>1</use_parent_model_frame>
			</axis>
		</joint>
		<link name='rotor_6'>
			<!-- <pose frame=''>0.07 -0.07 0.03 2.5261129 0.5235988 1.4008779</pose> -->
			<pose frame=''>0.07 -0.07 0.03 -0.6154797 -0.5235988 0.1699185</pose>
			<inertial>
				<pose frame=''>0 0 0 0 -0 0</pose>
				<mass>0.005</mass>
				<inertia>
				<ixx>9.75e-07</ixx>
				<ixy>0</ixy>
				<ixz>0</ixz>
				<iyy>0.000273104</iyy>
				<iyz>0</iyz>
				<izz>0.000274004</izz>
				</inertia>
			</inertial>
			<collision name='rotor_6_collision'>
				<pose frame=''>0 0 0 0 -0 0</pose>
				<geometry>
				<cylinder>
					<length>0.003</length>
					<radius>0.032</radius>
				</cylinder>
				</geometry>
				<surface>
				<contact>
					<ode/>
				</contact>
				<friction>
					<ode/>
				</friction>
				</surface>
			</collision>
			<visual name='rotor_6_visual'>
				<pose frame=''>0 0 0 0 -0 0</pose>
				<geometry>
				<mesh>
					<scale>0.25 0.25 0.25</scale>
					<uri>model://iris/meshes/iris_prop_cw.dae</uri>
				</mesh>
				</geometry>
				<material>
				<script>
					<name>Gazebo/DarkGrey</name>
					<uri>file://media/materials/scripts/gazebo.material</uri>
				</script>
				</material>
			</visual>
			<gravity>1</gravity>
			<velocity_decay/>
		</link>
		<joint name='rotor_6_joint' type='revolute'>
			<child>rotor_6</child>
			<parent>frame</parent>
			<axis>
				<xyz>-0.5 0.5 0.71071068</xyz>
				<limit>
				<lower>-1e+16</lower>
				<upper>1e+16</upper>
				</limit>
				<dynamics>
				<spring_reference>0</spring_reference>
				<spring_stiffness>0</spring_stiffness>
				</dynamics>
				<use_parent_model_frame>1</use_parent_model_frame>
			</axis>
		</joint>
		<link name='rotor_7'>
			<!-- <pose frame=''>-0.07 -0.07 0.03 2.5261129 -0.5235988 -1.4008779</pose> -->
			<pose frame=''>-0.07 -0.07 0.03 -0.6154797 0.5235988 -0.1699185</pose>
			
			<inertial>
				<pose frame=''>0 0 0 0 -0 0</pose>
				<mass>0.005</mass>
				<inertia>
				<ixx>9.75e-07</ixx>
				<ixy>0</ixy>
				<ixz>0</ixz>
				<iyy>0.000273104</iyy>
				<iyz>0</iyz>
				<izz>0.000274004</izz>
				</inertia>
			</inertial>
			<collision name='rotor_7_collision'>
				<pose frame=''>0 0 0 0 -0 0</pose>
				<geometry>
				<cylinder>
					<length>0.003</length>
					<radius>0.032</radius>
				</cylinder>
				</geometry>
				<surface>
				<contact>
					<ode/>
				</contact>
				<friction>
					<ode/>
				</friction>
				</surface>
			</collision>
			<visual name='rotor_7_visual'>
				<pose frame=''>0 0 0 0 -0 0</pose>
				<geometry>
				<mesh>
					<scale>0.25 0.25 0.25</scale>
					<uri>model://iris/meshes/iris_prop_cw.dae</uri>
				</mesh>
				</geometry>
				<material>
				<script>
					<name>Gazebo/DarkGrey</name>
					<uri>file://media/materials/scripts/gazebo.material</uri>
				</script>
				</material>
			</visual>
			<gravity>1</gravity>
			<velocity_decay/>
		</link>
		<joint name='rotor_7_joint' type='revolute'>
			<child>rotor_7</child>
			<parent>frame</parent>
			<axis>
				<xyz>0.5 0.5 0.71071068</xyz>
				<limit>
				<lower>-1e+16</lower>
				<upper>1e+16</upper>
				</limit>
				<dynamics>
				<spring_reference>0</spring_reference>
				<spring_stiffness>0</spring_stiffness>
				</dynamics>
				<use_parent_model_frame>1</use_parent_model_frame>
			</axis>
		</joint>
		<plugin name='rosbag' filename='libgazebo_multirotor_base_plugin.so'>
			<robotNamespace/>
			<linkName>frame</linkName>
			<rotorVelocitySlowdownSim>10</rotorVelocitySlowdownSim>
		</plugin>
		<plugin name='motor_0_model' filename='libgazebo_motor_model.so'>
		<robotNamespace/>
		<reversible>true</reversible>
		<jointName>rotor_0_joint</jointName>
		<linkName>rotor_0</linkName>
		<turningDirection>cw</turningDirection>
		<timeConstantUp>0.0125</timeConstantUp>
		<timeConstantDown>0.025</timeConstantDown>
		<maxRotVelocity>1100</maxRotVelocity>
		<motorConstant>2.50972e-05</motorConstant>
		<momentConstant>0.06</momentConstant>
		<commandSubTopic>/gazebo/command/motor_speed</commandSubTopic>
		<motorNumber>0</motorNumber>
		<rotorDragCoefficient>0.000175</rotorDragCoefficient>
		<rollingMomentCoefficient>1e-06</rollingMomentCoefficient>
		<motorSpeedPubTopic>/motor_speed/0</motorSpeedPubTopic>
		<rotorVelocitySlowdownSim>10</rotorVelocitySlowdownSim>
		</plugin>
		<plugin name='motor_1_model' filename='libgazebo_motor_model.so'>
		<robotNamespace/>
		<reversible>true</reversible>
		<jointName>rotor_1_joint</jointName>
		<linkName>rotor_1</linkName>
		<turningDirection>ccw</turningDirection>
		<timeConstantUp>0.0125</timeConstantUp>
		<timeConstantDown>0.025</timeConstantDown>
		<maxRotVelocity>1100</maxRotVelocity>
		<motorConstant>2.50972e-05</motorConstant>
		<momentConstant>0.06</momentConstant>
		<commandSubTopic>/gazebo/command/motor_speed</commandSubTopic>
		<motorNumber>1</motorNumber>
		<rotorDragCoefficient>0.000175</rotorDragCoefficient>
		<rollingMomentCoefficient>1e-06</rollingMomentCoefficient>
		<motorSpeedPubTopic>/motor_speed/1</motorSpeedPubTopic>
		<rotorVelocitySlowdownSim>10</rotorVelocitySlowdownSim>
		</plugin>
		<plugin name='motor_2_model' filename='libgazebo_motor_model.so'>
		<robotNamespace/>
		<reversible>true</reversible>
		<jointName>rotor_2_joint</jointName>
		<linkName>rotor_2</linkName>
		<turningDirection>ccw</turningDirection>
		<timeConstantUp>0.0125</timeConstantUp>
		<timeConstantDown>0.025</timeConstantDown>
		<maxRotVelocity>1100</maxRotVelocity>
		<motorConstant>2.50972e-05</motorConstant>
		<momentConstant>0.06</momentConstant>
		<commandSubTopic>/gazebo/command/motor_speed</commandSubTopic>
		<motorNumber>2</motorNumber>
		<rotorDragCoefficient>0.000175</rotorDragCoefficient>
		<rollingMomentCoefficient>1e-06</rollingMomentCoefficient>
		<motorSpeedPubTopic>/motor_speed/2</motorSpeedPubTopic>
		<rotorVelocitySlowdownSim>10</rotorVelocitySlowdownSim>
		</plugin>
		<plugin name='motor_3_model' filename='libgazebo_motor_model.so'>
		<robotNamespace/>
		<reversible>true</reversible>
		<jointName>rotor_3_joint</jointName>
		<linkName>rotor_3</linkName>
		<turningDirection>cw</turningDirection>
		<timeConstantUp>0.0125</timeConstantUp>
		<timeConstantDown>0.025</timeConstantDown>
		<maxRotVelocity>1100</maxRotVelocity>
		<motorConstant>2.50972e-05</motorConstant>
		<momentConstant>0.06</momentConstant>
		<commandSubTopic>/gazebo/command/motor_speed</commandSubTopic>
		<motorNumber>3</motorNumber>
		<rotorDragCoefficient>0.000175</rotorDragCoefficient>
		<rollingMomentCoefficient>1e-06</rollingMomentCoefficient>
		<motorSpeedPubTopic>/motor_speed/3</motorSpeedPubTopic>
		<rotorVelocitySlowdownSim>10</rotorVelocitySlowdownSim>
		</plugin>
		<!-- <plugin name='motor_4_model' filename='libgazebo_motor_model.so'>
		<robotNamespace/>
		<reversible>true</reversible>
		<jointName>rotor_4_joint</jointName>
		<linkName>rotor_4</linkName>
		<turningDirection>ccw</turningDirection>
		<timeConstantUp>0.0125</timeConstantUp>
		<timeConstantDown>0.025</timeConstantDown>
		<maxRotVelocity>1100</maxRotVelocity>
		<motorConstant>2.50972e-05</motorConstant>
		<momentConstant>0.06</momentConstant>
		<commandSubTopic>/gazebo/command/motor_speed</commandSubTopic>
		<motorNumber>4</motorNumber>
		<rotorDragCoefficient>0.000175</rotorDragCoefficient>
		<rollingMomentCoefficient>1e-06</rollingMomentCoefficient>
		<motorSpeedPubTopic>/motor_speed/4</motorSpeedPubTopic>
		<rotorVelocitySlowdownSim>10</rotorVelocitySlowdownSim>
		</plugin>
		<plugin name='motor_5_model' filename='libgazebo_motor_model.so'>
		<robotNamespace/>
		<reversible>true</reversible>
		<jointName>rotor_5_joint</jointName>
		<linkName>rotor_5</linkName>
		<turningDirection>ccw</turningDirection>
		<timeConstantUp>0.0125</timeConstantUp>
		<timeConstantDown>0.025</timeConstantDown>
		<maxRotVelocity>1100</maxRotVelocity>
		<motorConstant>2.50972e-05</motorConstant>
		<momentConstant>0.06</momentConstant>
		<commandSubTopic>/gazebo/command/motor_speed</commandSubTopic>
		<motorNumber>5</motorNumber>
		<rotorDragCoefficient>0.000175</rotorDragCoefficient>
		<rollingMomentCoefficient>1e-06</rollingMomentCoefficient>
		<motorSpeedPubTopic>/motor_speed/5</motorSpeedPubTopic>
		<rotorVelocitySlowdownSim>10</rotorVelocitySlowdownSim>
		</plugin>
		<plugin name='motor_6_model' filename='libgazebo_motor_model.so'>
		<robotNamespace/>
		<reversible>true</reversible>
		<jointName>rotor_6_joint</jointName>
		<linkName>rotor_6</linkName>
		<turningDirection>ccw</turningDirection>
		<timeConstantUp>0.0125</timeConstantUp>
		<timeConstantDown>0.025</timeConstantDown>
		<maxRotVelocity>1100</maxRotVelocity>
		<motorConstant>2.50972e-05</motorConstant>
		<momentConstant>0.06</momentConstant>
		<commandSubTopic>/gazebo/command/motor_speed</commandSubTopic>
		<motorNumber>6</motorNumber>
		<rotorDragCoefficient>0.000175</rotorDragCoefficient>
		<rollingMomentCoefficient>1e-06</rollingMomentCoefficient>
		<motorSpeedPubTopic>/motor_speed/6</motorSpeedPubTopic>
		<rotorVelocitySlowdownSim>10</rotorVelocitySlowdownSim>
		</plugin>
		<plugin name='motor_7_model' filename='libgazebo_motor_model.so'>
		<robotNamespace/>
		<reversible>true</reversible>
		<jointName>rotor_7_joint</jointName>
		<linkName>rotor_7</linkName>
		<turningDirection>ccw</turningDirection>
		<timeConstantUp>0.0125</timeConstantUp>
		<timeConstantDown>0.025</timeConstantDown>
		<maxRotVelocity>1100</maxRotVelocity>
		<motorConstant>2.50972e-05</motorConstant>
		<momentConstant>0.06</momentConstant>
		<commandSubTopic>/gazebo/command/motor_speed</commandSubTopic>
		<motorNumber>7</motorNumber>
		<rotorDragCoefficient>0.000175</rotorDragCoefficient>
		<rollingMomentCoefficient>1e-06</rollingMomentCoefficient>
		<motorSpeedPubTopic>/motor_speed/7</motorSpeedPubTopic>
		<rotorVelocitySlowdownSim>10</rotorVelocitySlowdownSim>
		</plugin> -->

		<plugin name='mavlink_interface' filename='libgazebo_mavlink_interface.so'>
			<robotNamespace/>
			<imuSubTopic>/imu</imuSubTopic>
			<magSubTopic>/mag</magSubTopic>
			<baroSubTopic>/baro</baroSubTopic>
			<mavlink_addr>INADDR_ANY</mavlink_addr>
			<mavlink_tcp_port>4560</mavlink_tcp_port>
			<mavlink_udp_port>14560</mavlink_udp_port>
			<serialEnabled>0</serialEnabled>
			<serialDevice>/dev/ttyACM0</serialDevice>
			<baudRate>921600</baudRate>
			<qgc_addr>INADDR_ANY</qgc_addr>
			<qgc_udp_port>14550</qgc_udp_port>
			<sdk_addr>INADDR_ANY</sdk_addr>
			<sdk_udp_port>14540</sdk_udp_port>
			<hil_mode>0</hil_mode>
			<hil_state_level>0</hil_state_level>
			<send_vision_estimation>0</send_vision_estimation>
			<send_odometry>1</send_odometry>
			<enable_lockstep>false</enable_lockstep>
			<use_tcp>1</use_tcp>
			<motorSpeedCommandPubTopic>/gazebo/command/motor_speed</motorSpeedCommandPubTopic>
			<control_channels>
				<channel name='rotor1'>
					<input_index>0</input_index>
					<input_offset>0</input_offset>
					<input_scaling>1000</input_scaling>
					<zero_position_disarmed>0</zero_position_disarmed>
					<zero_position_armed>100</zero_position_armed>
					<joint_control_type>velocity</joint_control_type>
				</channel>
				<channel name='rotor2'>
					<input_index>1</input_index>
					<input_offset>0</input_offset>
					<input_scaling>1000</input_scaling>
					<zero_position_disarmed>0</zero_position_disarmed>
					<zero_position_armed>100</zero_position_armed>
					<joint_control_type>velocity</joint_control_type>
				</channel>
				<channel name='rotor3'>
					<input_index>2</input_index>
					<input_offset>0</input_offset>
					<input_scaling>1000</input_scaling>
					<zero_position_disarmed>0</zero_position_disarmed>
					<zero_position_armed>100</zero_position_armed>
					<joint_control_type>velocity</joint_control_type>
				</channel>
				<channel name='rotor4'>
					<input_index>3</input_index>
					<input_offset>0</input_offset>
					<input_scaling>1000</input_scaling>
					<zero_position_disarmed>0</zero_position_disarmed>
					<zero_position_armed>100</zero_position_armed>
					<joint_control_type>velocity</joint_control_type>
				</channel>
				<channel name='rotor5'>
					<input_index>4</input_index>
					<input_offset>0</input_offset>
					<input_scaling>1000</input_scaling>
					<zero_position_disarmed>0</zero_position_disarmed>
					<zero_position_armed>0</zero_position_armed>
					<joint_control_type>velocity</joint_control_type>
				</channel>
				<channel name='rotor6'>
					<input_index>5</input_index>
					<input_offset>0</input_offset>
					<input_scaling>1000</input_scaling>
					<zero_position_disarmed>0</zero_position_disarmed>
					<zero_position_armed>0</zero_position_armed>
					<joint_control_type>velocity</joint_control_type>
				</channel>
				<channel name='rotor7'>
					<input_index>6</input_index>
					<input_offset>0</input_offset>
					<input_scaling>1000</input_scaling>
					<zero_position_disarmed>0</zero_position_disarmed>
					<zero_position_armed>0</zero_position_armed>
					<joint_control_type>velocity</joint_control_type>
				</channel>
				<channel name='rotor8'>
					<input_index>7</input_index>
					<input_offset>0</input_offset>
					<input_scaling>1000</input_scaling>
					<zero_position_disarmed>0</zero_position_disarmed>
					<zero_position_armed>0</zero_position_armed>
					<joint_control_type>velocity</joint_control_type>
				</channel>
			</control_channels>
		</plugin>
    	<static>0</static>


	</model>
</sdf>
